{
 "cells": [
  {
   "cell_type": "code",
   "execution_count": 1,
   "id": "1d0dad08-ee30-4b59-a216-0a74b0765c8d",
   "metadata": {},
   "outputs": [
    {
     "name": "stderr",
     "output_type": "stream",
     "text": [
      "\n",
      "A module that was compiled using NumPy 1.x cannot be run in\n",
      "NumPy 2.1.0 as it may crash. To support both 1.x and 2.x\n",
      "versions of NumPy, modules must be compiled with NumPy 2.0.\n",
      "Some module may need to rebuild instead e.g. with 'pybind11>=2.12'.\n",
      "\n",
      "If you are a user of the module, the easiest solution will be to\n",
      "downgrade to 'numpy<2' or try to upgrade the affected module.\n",
      "We expect that some modules will need time to support NumPy 2.\n",
      "\n",
      "Traceback (most recent call last):  File \"<frozen runpy>\", line 198, in _run_module_as_main\n",
      "  File \"<frozen runpy>\", line 88, in _run_code\n",
      "  File \"C:\\Users\\HP\\anaconda3\\Lib\\site-packages\\ipykernel_launcher.py\", line 17, in <module>\n",
      "    app.launch_new_instance()\n",
      "  File \"C:\\Users\\HP\\anaconda3\\Lib\\site-packages\\traitlets\\config\\application.py\", line 1075, in launch_instance\n",
      "    app.start()\n",
      "  File \"C:\\Users\\HP\\anaconda3\\Lib\\site-packages\\ipykernel\\kernelapp.py\", line 701, in start\n",
      "    self.io_loop.start()\n",
      "  File \"C:\\Users\\HP\\anaconda3\\Lib\\site-packages\\tornado\\platform\\asyncio.py\", line 205, in start\n",
      "    self.asyncio_loop.run_forever()\n",
      "  File \"C:\\Users\\HP\\anaconda3\\Lib\\asyncio\\windows_events.py\", line 322, in run_forever\n",
      "    super().run_forever()\n",
      "  File \"C:\\Users\\HP\\anaconda3\\Lib\\asyncio\\base_events.py\", line 641, in run_forever\n",
      "    self._run_once()\n",
      "  File \"C:\\Users\\HP\\anaconda3\\Lib\\asyncio\\base_events.py\", line 1986, in _run_once\n",
      "    handle._run()\n",
      "  File \"C:\\Users\\HP\\anaconda3\\Lib\\asyncio\\events.py\", line 88, in _run\n",
      "    self._context.run(self._callback, *self._args)\n",
      "  File \"C:\\Users\\HP\\anaconda3\\Lib\\site-packages\\ipykernel\\kernelbase.py\", line 534, in dispatch_queue\n",
      "    await self.process_one()\n",
      "  File \"C:\\Users\\HP\\anaconda3\\Lib\\site-packages\\ipykernel\\kernelbase.py\", line 523, in process_one\n",
      "    await dispatch(*args)\n",
      "  File \"C:\\Users\\HP\\anaconda3\\Lib\\site-packages\\ipykernel\\kernelbase.py\", line 429, in dispatch_shell\n",
      "    await result\n",
      "  File \"C:\\Users\\HP\\anaconda3\\Lib\\site-packages\\ipykernel\\kernelbase.py\", line 767, in execute_request\n",
      "    reply_content = await reply_content\n",
      "  File \"C:\\Users\\HP\\anaconda3\\Lib\\site-packages\\ipykernel\\ipkernel.py\", line 429, in do_execute\n",
      "    res = shell.run_cell(\n",
      "  File \"C:\\Users\\HP\\anaconda3\\Lib\\site-packages\\ipykernel\\zmqshell.py\", line 549, in run_cell\n",
      "    return super().run_cell(*args, **kwargs)\n",
      "  File \"C:\\Users\\HP\\anaconda3\\Lib\\site-packages\\IPython\\core\\interactiveshell.py\", line 3075, in run_cell\n",
      "    result = self._run_cell(\n",
      "  File \"C:\\Users\\HP\\anaconda3\\Lib\\site-packages\\IPython\\core\\interactiveshell.py\", line 3130, in _run_cell\n",
      "    result = runner(coro)\n",
      "  File \"C:\\Users\\HP\\anaconda3\\Lib\\site-packages\\IPython\\core\\async_helpers.py\", line 128, in _pseudo_sync_runner\n",
      "    coro.send(None)\n",
      "  File \"C:\\Users\\HP\\anaconda3\\Lib\\site-packages\\IPython\\core\\interactiveshell.py\", line 3334, in run_cell_async\n",
      "    has_raised = await self.run_ast_nodes(code_ast.body, cell_name,\n",
      "  File \"C:\\Users\\HP\\anaconda3\\Lib\\site-packages\\IPython\\core\\interactiveshell.py\", line 3517, in run_ast_nodes\n",
      "    if await self.run_code(code, result, async_=asy):\n",
      "  File \"C:\\Users\\HP\\anaconda3\\Lib\\site-packages\\IPython\\core\\interactiveshell.py\", line 3577, in run_code\n",
      "    exec(code_obj, self.user_global_ns, self.user_ns)\n",
      "  File \"C:\\Users\\HP\\AppData\\Local\\Temp\\ipykernel_14836\\2093165827.py\", line 2, in <module>\n",
      "    import pandas as pd\n",
      "  File \"C:\\Users\\HP\\AppData\\Roaming\\Python\\Python312\\site-packages\\pandas\\__init__.py\", line 39, in <module>\n",
      "    from pandas.compat import (\n",
      "  File \"C:\\Users\\HP\\AppData\\Roaming\\Python\\Python312\\site-packages\\pandas\\compat\\__init__.py\", line 27, in <module>\n",
      "    from pandas.compat.pyarrow import (\n",
      "  File \"C:\\Users\\HP\\AppData\\Roaming\\Python\\Python312\\site-packages\\pandas\\compat\\pyarrow.py\", line 8, in <module>\n",
      "    import pyarrow as pa\n",
      "  File \"C:\\Users\\HP\\anaconda3\\Lib\\site-packages\\pyarrow\\__init__.py\", line 65, in <module>\n",
      "    import pyarrow.lib as _lib\n"
     ]
    },
    {
     "ename": "ImportError",
     "evalue": "\nA module that was compiled using NumPy 1.x cannot be run in\nNumPy 2.1.0 as it may crash. To support both 1.x and 2.x\nversions of NumPy, modules must be compiled with NumPy 2.0.\nSome module may need to rebuild instead e.g. with 'pybind11>=2.12'.\n\nIf you are a user of the module, the easiest solution will be to\ndowngrade to 'numpy<2' or try to upgrade the affected module.\nWe expect that some modules will need time to support NumPy 2.\n\n",
     "output_type": "error",
     "traceback": [
      "\u001b[1;31m---------------------------------------------------------------------------\u001b[0m",
      "\u001b[1;31mImportError\u001b[0m                               Traceback (most recent call last)",
      "File \u001b[1;32m~\\AppData\\Roaming\\Python\\Python312\\site-packages\\numpy\\core\\_multiarray_umath.py:44\u001b[0m, in \u001b[0;36m__getattr__\u001b[1;34m(attr_name)\u001b[0m\n\u001b[0;32m     39\u001b[0m     \u001b[38;5;66;03m# Also print the message (with traceback).  This is because old versions\u001b[39;00m\n\u001b[0;32m     40\u001b[0m     \u001b[38;5;66;03m# of NumPy unfortunately set up the import to replace (and hide) the\u001b[39;00m\n\u001b[0;32m     41\u001b[0m     \u001b[38;5;66;03m# error.  The traceback shouldn't be needed, but e.g. pytest plugins\u001b[39;00m\n\u001b[0;32m     42\u001b[0m     \u001b[38;5;66;03m# seem to swallow it and we should be failing anyway...\u001b[39;00m\n\u001b[0;32m     43\u001b[0m     sys\u001b[38;5;241m.\u001b[39mstderr\u001b[38;5;241m.\u001b[39mwrite(msg \u001b[38;5;241m+\u001b[39m tb_msg)\n\u001b[1;32m---> 44\u001b[0m     \u001b[38;5;28;01mraise\u001b[39;00m \u001b[38;5;167;01mImportError\u001b[39;00m(msg)\n\u001b[0;32m     46\u001b[0m ret \u001b[38;5;241m=\u001b[39m \u001b[38;5;28mgetattr\u001b[39m(_multiarray_umath, attr_name, \u001b[38;5;28;01mNone\u001b[39;00m)\n\u001b[0;32m     47\u001b[0m \u001b[38;5;28;01mif\u001b[39;00m ret \u001b[38;5;129;01mis\u001b[39;00m \u001b[38;5;28;01mNone\u001b[39;00m:\n",
      "\u001b[1;31mImportError\u001b[0m: \nA module that was compiled using NumPy 1.x cannot be run in\nNumPy 2.1.0 as it may crash. To support both 1.x and 2.x\nversions of NumPy, modules must be compiled with NumPy 2.0.\nSome module may need to rebuild instead e.g. with 'pybind11>=2.12'.\n\nIf you are a user of the module, the easiest solution will be to\ndowngrade to 'numpy<2' or try to upgrade the affected module.\nWe expect that some modules will need time to support NumPy 2.\n\n"
     ]
    },
    {
     "name": "stderr",
     "output_type": "stream",
     "text": [
      "\n",
      "A module that was compiled using NumPy 1.x cannot be run in\n",
      "NumPy 2.1.0 as it may crash. To support both 1.x and 2.x\n",
      "versions of NumPy, modules must be compiled with NumPy 2.0.\n",
      "Some module may need to rebuild instead e.g. with 'pybind11>=2.12'.\n",
      "\n",
      "If you are a user of the module, the easiest solution will be to\n",
      "downgrade to 'numpy<2' or try to upgrade the affected module.\n",
      "We expect that some modules will need time to support NumPy 2.\n",
      "\n",
      "Traceback (most recent call last):  File \"<frozen runpy>\", line 198, in _run_module_as_main\n",
      "  File \"<frozen runpy>\", line 88, in _run_code\n",
      "  File \"C:\\Users\\HP\\anaconda3\\Lib\\site-packages\\ipykernel_launcher.py\", line 17, in <module>\n",
      "    app.launch_new_instance()\n",
      "  File \"C:\\Users\\HP\\anaconda3\\Lib\\site-packages\\traitlets\\config\\application.py\", line 1075, in launch_instance\n",
      "    app.start()\n",
      "  File \"C:\\Users\\HP\\anaconda3\\Lib\\site-packages\\ipykernel\\kernelapp.py\", line 701, in start\n",
      "    self.io_loop.start()\n",
      "  File \"C:\\Users\\HP\\anaconda3\\Lib\\site-packages\\tornado\\platform\\asyncio.py\", line 205, in start\n",
      "    self.asyncio_loop.run_forever()\n",
      "  File \"C:\\Users\\HP\\anaconda3\\Lib\\asyncio\\windows_events.py\", line 322, in run_forever\n",
      "    super().run_forever()\n",
      "  File \"C:\\Users\\HP\\anaconda3\\Lib\\asyncio\\base_events.py\", line 641, in run_forever\n",
      "    self._run_once()\n",
      "  File \"C:\\Users\\HP\\anaconda3\\Lib\\asyncio\\base_events.py\", line 1986, in _run_once\n",
      "    handle._run()\n",
      "  File \"C:\\Users\\HP\\anaconda3\\Lib\\asyncio\\events.py\", line 88, in _run\n",
      "    self._context.run(self._callback, *self._args)\n",
      "  File \"C:\\Users\\HP\\anaconda3\\Lib\\site-packages\\ipykernel\\kernelbase.py\", line 534, in dispatch_queue\n",
      "    await self.process_one()\n",
      "  File \"C:\\Users\\HP\\anaconda3\\Lib\\site-packages\\ipykernel\\kernelbase.py\", line 523, in process_one\n",
      "    await dispatch(*args)\n",
      "  File \"C:\\Users\\HP\\anaconda3\\Lib\\site-packages\\ipykernel\\kernelbase.py\", line 429, in dispatch_shell\n",
      "    await result\n",
      "  File \"C:\\Users\\HP\\anaconda3\\Lib\\site-packages\\ipykernel\\kernelbase.py\", line 767, in execute_request\n",
      "    reply_content = await reply_content\n",
      "  File \"C:\\Users\\HP\\anaconda3\\Lib\\site-packages\\ipykernel\\ipkernel.py\", line 429, in do_execute\n",
      "    res = shell.run_cell(\n",
      "  File \"C:\\Users\\HP\\anaconda3\\Lib\\site-packages\\ipykernel\\zmqshell.py\", line 549, in run_cell\n",
      "    return super().run_cell(*args, **kwargs)\n",
      "  File \"C:\\Users\\HP\\anaconda3\\Lib\\site-packages\\IPython\\core\\interactiveshell.py\", line 3075, in run_cell\n",
      "    result = self._run_cell(\n",
      "  File \"C:\\Users\\HP\\anaconda3\\Lib\\site-packages\\IPython\\core\\interactiveshell.py\", line 3130, in _run_cell\n",
      "    result = runner(coro)\n",
      "  File \"C:\\Users\\HP\\anaconda3\\Lib\\site-packages\\IPython\\core\\async_helpers.py\", line 128, in _pseudo_sync_runner\n",
      "    coro.send(None)\n",
      "  File \"C:\\Users\\HP\\anaconda3\\Lib\\site-packages\\IPython\\core\\interactiveshell.py\", line 3334, in run_cell_async\n",
      "    has_raised = await self.run_ast_nodes(code_ast.body, cell_name,\n",
      "  File \"C:\\Users\\HP\\anaconda3\\Lib\\site-packages\\IPython\\core\\interactiveshell.py\", line 3517, in run_ast_nodes\n",
      "    if await self.run_code(code, result, async_=asy):\n",
      "  File \"C:\\Users\\HP\\anaconda3\\Lib\\site-packages\\IPython\\core\\interactiveshell.py\", line 3577, in run_code\n",
      "    exec(code_obj, self.user_global_ns, self.user_ns)\n",
      "  File \"C:\\Users\\HP\\AppData\\Local\\Temp\\ipykernel_14836\\2093165827.py\", line 2, in <module>\n",
      "    import pandas as pd\n",
      "  File \"C:\\Users\\HP\\AppData\\Roaming\\Python\\Python312\\site-packages\\pandas\\__init__.py\", line 62, in <module>\n",
      "    from pandas.core.api import (\n",
      "  File \"C:\\Users\\HP\\AppData\\Roaming\\Python\\Python312\\site-packages\\pandas\\core\\api.py\", line 9, in <module>\n",
      "    from pandas.core.dtypes.dtypes import (\n",
      "  File \"C:\\Users\\HP\\AppData\\Roaming\\Python\\Python312\\site-packages\\pandas\\core\\dtypes\\dtypes.py\", line 24, in <module>\n",
      "    from pandas._libs import (\n",
      "  File \"C:\\Users\\HP\\anaconda3\\Lib\\site-packages\\pyarrow\\__init__.py\", line 65, in <module>\n",
      "    import pyarrow.lib as _lib\n"
     ]
    },
    {
     "ename": "ImportError",
     "evalue": "\nA module that was compiled using NumPy 1.x cannot be run in\nNumPy 2.1.0 as it may crash. To support both 1.x and 2.x\nversions of NumPy, modules must be compiled with NumPy 2.0.\nSome module may need to rebuild instead e.g. with 'pybind11>=2.12'.\n\nIf you are a user of the module, the easiest solution will be to\ndowngrade to 'numpy<2' or try to upgrade the affected module.\nWe expect that some modules will need time to support NumPy 2.\n\n",
     "output_type": "error",
     "traceback": [
      "\u001b[1;31m---------------------------------------------------------------------------\u001b[0m",
      "\u001b[1;31mImportError\u001b[0m                               Traceback (most recent call last)",
      "File \u001b[1;32m~\\AppData\\Roaming\\Python\\Python312\\site-packages\\numpy\\core\\_multiarray_umath.py:44\u001b[0m, in \u001b[0;36m__getattr__\u001b[1;34m(attr_name)\u001b[0m\n\u001b[0;32m     39\u001b[0m     \u001b[38;5;66;03m# Also print the message (with traceback).  This is because old versions\u001b[39;00m\n\u001b[0;32m     40\u001b[0m     \u001b[38;5;66;03m# of NumPy unfortunately set up the import to replace (and hide) the\u001b[39;00m\n\u001b[0;32m     41\u001b[0m     \u001b[38;5;66;03m# error.  The traceback shouldn't be needed, but e.g. pytest plugins\u001b[39;00m\n\u001b[0;32m     42\u001b[0m     \u001b[38;5;66;03m# seem to swallow it and we should be failing anyway...\u001b[39;00m\n\u001b[0;32m     43\u001b[0m     sys\u001b[38;5;241m.\u001b[39mstderr\u001b[38;5;241m.\u001b[39mwrite(msg \u001b[38;5;241m+\u001b[39m tb_msg)\n\u001b[1;32m---> 44\u001b[0m     \u001b[38;5;28;01mraise\u001b[39;00m \u001b[38;5;167;01mImportError\u001b[39;00m(msg)\n\u001b[0;32m     46\u001b[0m ret \u001b[38;5;241m=\u001b[39m \u001b[38;5;28mgetattr\u001b[39m(_multiarray_umath, attr_name, \u001b[38;5;28;01mNone\u001b[39;00m)\n\u001b[0;32m     47\u001b[0m \u001b[38;5;28;01mif\u001b[39;00m ret \u001b[38;5;129;01mis\u001b[39;00m \u001b[38;5;28;01mNone\u001b[39;00m:\n",
      "\u001b[1;31mImportError\u001b[0m: \nA module that was compiled using NumPy 1.x cannot be run in\nNumPy 2.1.0 as it may crash. To support both 1.x and 2.x\nversions of NumPy, modules must be compiled with NumPy 2.0.\nSome module may need to rebuild instead e.g. with 'pybind11>=2.12'.\n\nIf you are a user of the module, the easiest solution will be to\ndowngrade to 'numpy<2' or try to upgrade the affected module.\nWe expect that some modules will need time to support NumPy 2.\n\n"
     ]
    },
    {
     "name": "stderr",
     "output_type": "stream",
     "text": [
      "\n",
      "A module that was compiled using NumPy 1.x cannot be run in\n",
      "NumPy 2.1.0 as it may crash. To support both 1.x and 2.x\n",
      "versions of NumPy, modules must be compiled with NumPy 2.0.\n",
      "Some module may need to rebuild instead e.g. with 'pybind11>=2.12'.\n",
      "\n",
      "If you are a user of the module, the easiest solution will be to\n",
      "downgrade to 'numpy<2' or try to upgrade the affected module.\n",
      "We expect that some modules will need time to support NumPy 2.\n",
      "\n",
      "Traceback (most recent call last):  File \"<frozen runpy>\", line 198, in _run_module_as_main\n",
      "  File \"<frozen runpy>\", line 88, in _run_code\n",
      "  File \"C:\\Users\\HP\\anaconda3\\Lib\\site-packages\\ipykernel_launcher.py\", line 17, in <module>\n",
      "    app.launch_new_instance()\n",
      "  File \"C:\\Users\\HP\\anaconda3\\Lib\\site-packages\\traitlets\\config\\application.py\", line 1075, in launch_instance\n",
      "    app.start()\n",
      "  File \"C:\\Users\\HP\\anaconda3\\Lib\\site-packages\\ipykernel\\kernelapp.py\", line 701, in start\n",
      "    self.io_loop.start()\n",
      "  File \"C:\\Users\\HP\\anaconda3\\Lib\\site-packages\\tornado\\platform\\asyncio.py\", line 205, in start\n",
      "    self.asyncio_loop.run_forever()\n",
      "  File \"C:\\Users\\HP\\anaconda3\\Lib\\asyncio\\windows_events.py\", line 322, in run_forever\n",
      "    super().run_forever()\n",
      "  File \"C:\\Users\\HP\\anaconda3\\Lib\\asyncio\\base_events.py\", line 641, in run_forever\n",
      "    self._run_once()\n",
      "  File \"C:\\Users\\HP\\anaconda3\\Lib\\asyncio\\base_events.py\", line 1986, in _run_once\n",
      "    handle._run()\n",
      "  File \"C:\\Users\\HP\\anaconda3\\Lib\\asyncio\\events.py\", line 88, in _run\n",
      "    self._context.run(self._callback, *self._args)\n",
      "  File \"C:\\Users\\HP\\anaconda3\\Lib\\site-packages\\ipykernel\\kernelbase.py\", line 534, in dispatch_queue\n",
      "    await self.process_one()\n",
      "  File \"C:\\Users\\HP\\anaconda3\\Lib\\site-packages\\ipykernel\\kernelbase.py\", line 523, in process_one\n",
      "    await dispatch(*args)\n",
      "  File \"C:\\Users\\HP\\anaconda3\\Lib\\site-packages\\ipykernel\\kernelbase.py\", line 429, in dispatch_shell\n",
      "    await result\n",
      "  File \"C:\\Users\\HP\\anaconda3\\Lib\\site-packages\\ipykernel\\kernelbase.py\", line 767, in execute_request\n",
      "    reply_content = await reply_content\n",
      "  File \"C:\\Users\\HP\\anaconda3\\Lib\\site-packages\\ipykernel\\ipkernel.py\", line 429, in do_execute\n",
      "    res = shell.run_cell(\n",
      "  File \"C:\\Users\\HP\\anaconda3\\Lib\\site-packages\\ipykernel\\zmqshell.py\", line 549, in run_cell\n",
      "    return super().run_cell(*args, **kwargs)\n",
      "  File \"C:\\Users\\HP\\anaconda3\\Lib\\site-packages\\IPython\\core\\interactiveshell.py\", line 3075, in run_cell\n",
      "    result = self._run_cell(\n",
      "  File \"C:\\Users\\HP\\anaconda3\\Lib\\site-packages\\IPython\\core\\interactiveshell.py\", line 3130, in _run_cell\n",
      "    result = runner(coro)\n",
      "  File \"C:\\Users\\HP\\anaconda3\\Lib\\site-packages\\IPython\\core\\async_helpers.py\", line 128, in _pseudo_sync_runner\n",
      "    coro.send(None)\n",
      "  File \"C:\\Users\\HP\\anaconda3\\Lib\\site-packages\\IPython\\core\\interactiveshell.py\", line 3334, in run_cell_async\n",
      "    has_raised = await self.run_ast_nodes(code_ast.body, cell_name,\n",
      "  File \"C:\\Users\\HP\\anaconda3\\Lib\\site-packages\\IPython\\core\\interactiveshell.py\", line 3517, in run_ast_nodes\n",
      "    if await self.run_code(code, result, async_=asy):\n",
      "  File \"C:\\Users\\HP\\anaconda3\\Lib\\site-packages\\IPython\\core\\interactiveshell.py\", line 3577, in run_code\n",
      "    exec(code_obj, self.user_global_ns, self.user_ns)\n",
      "  File \"C:\\Users\\HP\\AppData\\Local\\Temp\\ipykernel_14836\\2093165827.py\", line 2, in <module>\n",
      "    import pandas as pd\n",
      "  File \"C:\\Users\\HP\\AppData\\Roaming\\Python\\Python312\\site-packages\\pandas\\__init__.py\", line 62, in <module>\n",
      "    from pandas.core.api import (\n",
      "  File \"C:\\Users\\HP\\AppData\\Roaming\\Python\\Python312\\site-packages\\pandas\\core\\api.py\", line 28, in <module>\n",
      "    from pandas.core.arrays import Categorical\n",
      "  File \"C:\\Users\\HP\\AppData\\Roaming\\Python\\Python312\\site-packages\\pandas\\core\\arrays\\__init__.py\", line 1, in <module>\n",
      "    from pandas.core.arrays.arrow import ArrowExtensionArray\n",
      "  File \"C:\\Users\\HP\\AppData\\Roaming\\Python\\Python312\\site-packages\\pandas\\core\\arrays\\arrow\\__init__.py\", line 5, in <module>\n",
      "    from pandas.core.arrays.arrow.array import ArrowExtensionArray\n",
      "  File \"C:\\Users\\HP\\AppData\\Roaming\\Python\\Python312\\site-packages\\pandas\\core\\arrays\\arrow\\array.py\", line 50, in <module>\n",
      "    from pandas.core import (\n",
      "  File \"C:\\Users\\HP\\AppData\\Roaming\\Python\\Python312\\site-packages\\pandas\\core\\ops\\__init__.py\", line 8, in <module>\n",
      "    from pandas.core.ops.array_ops import (\n",
      "  File \"C:\\Users\\HP\\AppData\\Roaming\\Python\\Python312\\site-packages\\pandas\\core\\ops\\array_ops.py\", line 56, in <module>\n",
      "    from pandas.core.computation import expressions\n",
      "  File \"C:\\Users\\HP\\AppData\\Roaming\\Python\\Python312\\site-packages\\pandas\\core\\computation\\expressions.py\", line 21, in <module>\n",
      "    from pandas.core.computation.check import NUMEXPR_INSTALLED\n",
      "  File \"C:\\Users\\HP\\AppData\\Roaming\\Python\\Python312\\site-packages\\pandas\\core\\computation\\check.py\", line 5, in <module>\n",
      "    ne = import_optional_dependency(\"numexpr\", errors=\"warn\")\n",
      "  File \"C:\\Users\\HP\\AppData\\Roaming\\Python\\Python312\\site-packages\\pandas\\compat\\_optional.py\", line 135, in import_optional_dependency\n",
      "    module = importlib.import_module(name)\n",
      "  File \"C:\\Users\\HP\\anaconda3\\Lib\\importlib\\__init__.py\", line 90, in import_module\n",
      "    return _bootstrap._gcd_import(name[level:], package, level)\n",
      "  File \"C:\\Users\\HP\\anaconda3\\Lib\\site-packages\\numexpr\\__init__.py\", line 24, in <module>\n",
      "    from numexpr.interpreter import MAX_THREADS, use_vml, __BLOCK_SIZE1__\n"
     ]
    },
    {
     "ename": "AttributeError",
     "evalue": "_ARRAY_API not found",
     "output_type": "error",
     "traceback": [
      "\u001b[1;31m---------------------------------------------------------------------------\u001b[0m",
      "\u001b[1;31mAttributeError\u001b[0m                            Traceback (most recent call last)",
      "\u001b[1;31mAttributeError\u001b[0m: _ARRAY_API not found"
     ]
    },
    {
     "name": "stderr",
     "output_type": "stream",
     "text": [
      "\n",
      "A module that was compiled using NumPy 1.x cannot be run in\n",
      "NumPy 2.1.0 as it may crash. To support both 1.x and 2.x\n",
      "versions of NumPy, modules must be compiled with NumPy 2.0.\n",
      "Some module may need to rebuild instead e.g. with 'pybind11>=2.12'.\n",
      "\n",
      "If you are a user of the module, the easiest solution will be to\n",
      "downgrade to 'numpy<2' or try to upgrade the affected module.\n",
      "We expect that some modules will need time to support NumPy 2.\n",
      "\n",
      "Traceback (most recent call last):  File \"<frozen runpy>\", line 198, in _run_module_as_main\n",
      "  File \"<frozen runpy>\", line 88, in _run_code\n",
      "  File \"C:\\Users\\HP\\anaconda3\\Lib\\site-packages\\ipykernel_launcher.py\", line 17, in <module>\n",
      "    app.launch_new_instance()\n",
      "  File \"C:\\Users\\HP\\anaconda3\\Lib\\site-packages\\traitlets\\config\\application.py\", line 1075, in launch_instance\n",
      "    app.start()\n",
      "  File \"C:\\Users\\HP\\anaconda3\\Lib\\site-packages\\ipykernel\\kernelapp.py\", line 701, in start\n",
      "    self.io_loop.start()\n",
      "  File \"C:\\Users\\HP\\anaconda3\\Lib\\site-packages\\tornado\\platform\\asyncio.py\", line 205, in start\n",
      "    self.asyncio_loop.run_forever()\n",
      "  File \"C:\\Users\\HP\\anaconda3\\Lib\\asyncio\\windows_events.py\", line 322, in run_forever\n",
      "    super().run_forever()\n",
      "  File \"C:\\Users\\HP\\anaconda3\\Lib\\asyncio\\base_events.py\", line 641, in run_forever\n",
      "    self._run_once()\n",
      "  File \"C:\\Users\\HP\\anaconda3\\Lib\\asyncio\\base_events.py\", line 1986, in _run_once\n",
      "    handle._run()\n",
      "  File \"C:\\Users\\HP\\anaconda3\\Lib\\asyncio\\events.py\", line 88, in _run\n",
      "    self._context.run(self._callback, *self._args)\n",
      "  File \"C:\\Users\\HP\\anaconda3\\Lib\\site-packages\\ipykernel\\kernelbase.py\", line 534, in dispatch_queue\n",
      "    await self.process_one()\n",
      "  File \"C:\\Users\\HP\\anaconda3\\Lib\\site-packages\\ipykernel\\kernelbase.py\", line 523, in process_one\n",
      "    await dispatch(*args)\n",
      "  File \"C:\\Users\\HP\\anaconda3\\Lib\\site-packages\\ipykernel\\kernelbase.py\", line 429, in dispatch_shell\n",
      "    await result\n",
      "  File \"C:\\Users\\HP\\anaconda3\\Lib\\site-packages\\ipykernel\\kernelbase.py\", line 767, in execute_request\n",
      "    reply_content = await reply_content\n",
      "  File \"C:\\Users\\HP\\anaconda3\\Lib\\site-packages\\ipykernel\\ipkernel.py\", line 429, in do_execute\n",
      "    res = shell.run_cell(\n",
      "  File \"C:\\Users\\HP\\anaconda3\\Lib\\site-packages\\ipykernel\\zmqshell.py\", line 549, in run_cell\n",
      "    return super().run_cell(*args, **kwargs)\n",
      "  File \"C:\\Users\\HP\\anaconda3\\Lib\\site-packages\\IPython\\core\\interactiveshell.py\", line 3075, in run_cell\n",
      "    result = self._run_cell(\n",
      "  File \"C:\\Users\\HP\\anaconda3\\Lib\\site-packages\\IPython\\core\\interactiveshell.py\", line 3130, in _run_cell\n",
      "    result = runner(coro)\n",
      "  File \"C:\\Users\\HP\\anaconda3\\Lib\\site-packages\\IPython\\core\\async_helpers.py\", line 128, in _pseudo_sync_runner\n",
      "    coro.send(None)\n",
      "  File \"C:\\Users\\HP\\anaconda3\\Lib\\site-packages\\IPython\\core\\interactiveshell.py\", line 3334, in run_cell_async\n",
      "    has_raised = await self.run_ast_nodes(code_ast.body, cell_name,\n",
      "  File \"C:\\Users\\HP\\anaconda3\\Lib\\site-packages\\IPython\\core\\interactiveshell.py\", line 3517, in run_ast_nodes\n",
      "    if await self.run_code(code, result, async_=asy):\n",
      "  File \"C:\\Users\\HP\\anaconda3\\Lib\\site-packages\\IPython\\core\\interactiveshell.py\", line 3577, in run_code\n",
      "    exec(code_obj, self.user_global_ns, self.user_ns)\n",
      "  File \"C:\\Users\\HP\\AppData\\Local\\Temp\\ipykernel_14836\\2093165827.py\", line 2, in <module>\n",
      "    import pandas as pd\n",
      "  File \"C:\\Users\\HP\\AppData\\Roaming\\Python\\Python312\\site-packages\\pandas\\__init__.py\", line 62, in <module>\n",
      "    from pandas.core.api import (\n",
      "  File \"C:\\Users\\HP\\AppData\\Roaming\\Python\\Python312\\site-packages\\pandas\\core\\api.py\", line 28, in <module>\n",
      "    from pandas.core.arrays import Categorical\n",
      "  File \"C:\\Users\\HP\\AppData\\Roaming\\Python\\Python312\\site-packages\\pandas\\core\\arrays\\__init__.py\", line 1, in <module>\n",
      "    from pandas.core.arrays.arrow import ArrowExtensionArray\n",
      "  File \"C:\\Users\\HP\\AppData\\Roaming\\Python\\Python312\\site-packages\\pandas\\core\\arrays\\arrow\\__init__.py\", line 5, in <module>\n",
      "    from pandas.core.arrays.arrow.array import ArrowExtensionArray\n",
      "  File \"C:\\Users\\HP\\AppData\\Roaming\\Python\\Python312\\site-packages\\pandas\\core\\arrays\\arrow\\array.py\", line 64, in <module>\n",
      "    from pandas.core.arrays.masked import BaseMaskedArray\n",
      "  File \"C:\\Users\\HP\\AppData\\Roaming\\Python\\Python312\\site-packages\\pandas\\core\\arrays\\masked.py\", line 60, in <module>\n",
      "    from pandas.core import (\n",
      "  File \"C:\\Users\\HP\\AppData\\Roaming\\Python\\Python312\\site-packages\\pandas\\core\\nanops.py\", line 52, in <module>\n",
      "    bn = import_optional_dependency(\"bottleneck\", errors=\"warn\")\n",
      "  File \"C:\\Users\\HP\\AppData\\Roaming\\Python\\Python312\\site-packages\\pandas\\compat\\_optional.py\", line 135, in import_optional_dependency\n",
      "    module = importlib.import_module(name)\n",
      "  File \"C:\\Users\\HP\\anaconda3\\Lib\\importlib\\__init__.py\", line 90, in import_module\n",
      "    return _bootstrap._gcd_import(name[level:], package, level)\n",
      "  File \"C:\\Users\\HP\\anaconda3\\Lib\\site-packages\\bottleneck\\__init__.py\", line 7, in <module>\n",
      "    from .move import (move_argmax, move_argmin, move_max, move_mean, move_median,\n"
     ]
    },
    {
     "ename": "ImportError",
     "evalue": "\nA module that was compiled using NumPy 1.x cannot be run in\nNumPy 2.1.0 as it may crash. To support both 1.x and 2.x\nversions of NumPy, modules must be compiled with NumPy 2.0.\nSome module may need to rebuild instead e.g. with 'pybind11>=2.12'.\n\nIf you are a user of the module, the easiest solution will be to\ndowngrade to 'numpy<2' or try to upgrade the affected module.\nWe expect that some modules will need time to support NumPy 2.\n\n",
     "output_type": "error",
     "traceback": [
      "\u001b[1;31m---------------------------------------------------------------------------\u001b[0m",
      "\u001b[1;31mImportError\u001b[0m                               Traceback (most recent call last)",
      "File \u001b[1;32m~\\AppData\\Roaming\\Python\\Python312\\site-packages\\numpy\\core\\_multiarray_umath.py:44\u001b[0m, in \u001b[0;36m__getattr__\u001b[1;34m(attr_name)\u001b[0m\n\u001b[0;32m     39\u001b[0m     \u001b[38;5;66;03m# Also print the message (with traceback).  This is because old versions\u001b[39;00m\n\u001b[0;32m     40\u001b[0m     \u001b[38;5;66;03m# of NumPy unfortunately set up the import to replace (and hide) the\u001b[39;00m\n\u001b[0;32m     41\u001b[0m     \u001b[38;5;66;03m# error.  The traceback shouldn't be needed, but e.g. pytest plugins\u001b[39;00m\n\u001b[0;32m     42\u001b[0m     \u001b[38;5;66;03m# seem to swallow it and we should be failing anyway...\u001b[39;00m\n\u001b[0;32m     43\u001b[0m     sys\u001b[38;5;241m.\u001b[39mstderr\u001b[38;5;241m.\u001b[39mwrite(msg \u001b[38;5;241m+\u001b[39m tb_msg)\n\u001b[1;32m---> 44\u001b[0m     \u001b[38;5;28;01mraise\u001b[39;00m \u001b[38;5;167;01mImportError\u001b[39;00m(msg)\n\u001b[0;32m     46\u001b[0m ret \u001b[38;5;241m=\u001b[39m \u001b[38;5;28mgetattr\u001b[39m(_multiarray_umath, attr_name, \u001b[38;5;28;01mNone\u001b[39;00m)\n\u001b[0;32m     47\u001b[0m \u001b[38;5;28;01mif\u001b[39;00m ret \u001b[38;5;129;01mis\u001b[39;00m \u001b[38;5;28;01mNone\u001b[39;00m:\n",
      "\u001b[1;31mImportError\u001b[0m: \nA module that was compiled using NumPy 1.x cannot be run in\nNumPy 2.1.0 as it may crash. To support both 1.x and 2.x\nversions of NumPy, modules must be compiled with NumPy 2.0.\nSome module may need to rebuild instead e.g. with 'pybind11>=2.12'.\n\nIf you are a user of the module, the easiest solution will be to\ndowngrade to 'numpy<2' or try to upgrade the affected module.\nWe expect that some modules will need time to support NumPy 2.\n\n"
     ]
    }
   ],
   "source": [
    "#load the libraries\n",
    "import pandas as pd\n",
    "import numpy as np\n",
    "import matplotlib.pyplot as plt\n",
    "import seaborn as sns"
   ]
  },
  {
   "cell_type": "code",
   "execution_count": 2,
   "id": "eba89c47-4643-4518-abb0-7ef8ff840d8b",
   "metadata": {},
   "outputs": [
    {
     "name": "stdout",
     "output_type": "stream",
     "text": [
      "                         Newspaper     daily    sunday\n",
      "0                    Baltimore Sun   391.952   488.506\n",
      "1                     Boston Globe   516.981   798.298\n",
      "2                    Boston Herald   355.628   235.084\n",
      "3               Charlotte Observer   238.555   299.451\n",
      "4                Chicago Sun Times   537.780   559.093\n",
      "5                  Chicago Tribune   733.775  1133.249\n",
      "6              Cincinnati Enquirer   198.832   348.744\n",
      "7                      Denver Post   252.624   417.779\n",
      "8              Des Moines Register   206.204   344.522\n",
      "9                 Hartford Courant   231.177   323.084\n",
      "10               Houston Chronicle   449.755   620.752\n",
      "11                Kansas City Star   288.571   423.305\n",
      "12         Los Angeles Daily  News   185.736   202.614\n",
      "13               Los Angeles Times  1164.388  1531.527\n",
      "14                    Miami Herald   444.581   553.479\n",
      "15        Minneapolis Star Tribune   412.871   685.975\n",
      "16      New Orleans Times-Picayune   272.280   324.241\n",
      "17             New York Daily News   781.796   983.240\n",
      "18                  New York Times  1209.225  1762.015\n",
      "19                         Newsday   825.512   960.308\n",
      "20              Omaha World Herald   223.748   284.611\n",
      "21          Orange County Register   354.843   407.760\n",
      "22           Philadelphia Inquirer   515.523   982.663\n",
      "23                Pittsburgh Press   220.465   557.000\n",
      "24              Portland Oregonian   337.672   440.923\n",
      "25     Providence Journal-Bulletin   197.120   268.060\n",
      "26  Rochester Democrat & Chronicle   133.239   262.048\n",
      "27             Rocky Mountain News   374.009   432.502\n",
      "28                  Sacramento Bee   273.844   338.355\n",
      "29         San Francisco Chronicle   570.364   704.322\n",
      "30         St. Louis Post-Dispatch   391.286   585.681\n",
      "31          St. Paul Pioneer Press   201.860   267.781\n",
      "32                   Tampa Tribune   321.626   408.343\n",
      "33                 Washington Post   838.902  1165.567\n"
     ]
    }
   ],
   "source": [
    "data = pd.read_csv(\"NewspaperData.csv\")\n",
    "print(data)"
   ]
  },
  {
   "cell_type": "code",
   "execution_count": 3,
   "id": "366bfb63-90c6-4ed9-b2bf-b5650fd8c6d7",
   "metadata": {},
   "outputs": [
    {
     "name": "stdout",
     "output_type": "stream",
     "text": [
      "<class 'pandas.core.frame.DataFrame'>\n",
      "RangeIndex: 34 entries, 0 to 33\n",
      "Data columns (total 3 columns):\n",
      " #   Column     Non-Null Count  Dtype  \n",
      "---  ------     --------------  -----  \n",
      " 0   Newspaper  34 non-null     object \n",
      " 1   daily      34 non-null     float64\n",
      " 2   sunday     34 non-null     float64\n",
      "dtypes: float64(2), object(1)\n",
      "memory usage: 948.0+ bytes\n"
     ]
    }
   ],
   "source": [
    "data.info()"
   ]
  },
  {
   "cell_type": "code",
   "execution_count": 4,
   "id": "e1ff2d81-6176-4098-9f65-71c66aa102c1",
   "metadata": {},
   "outputs": [
    {
     "name": "stdout",
     "output_type": "stream",
     "text": [
      "<class 'pandas.core.frame.DataFrame'>\n",
      "(34, 3)\n",
      "102\n"
     ]
    }
   ],
   "source": [
    "print(type(data))\n",
    "print(data.shape)\n",
    "print(data.size)"
   ]
  },
  {
   "cell_type": "code",
   "execution_count": null,
   "id": "8198d335-8f70-49ea-b0e7-20ab44c83daa",
   "metadata": {},
   "outputs": [],
   "source": []
  }
 ],
 "metadata": {
  "kernelspec": {
   "display_name": "Python 3 (ipykernel)",
   "language": "python",
   "name": "python3"
  },
  "language_info": {
   "codemirror_mode": {
    "name": "ipython",
    "version": 3
   },
   "file_extension": ".py",
   "mimetype": "text/x-python",
   "name": "python",
   "nbconvert_exporter": "python",
   "pygments_lexer": "ipython3",
   "version": "3.12.7"
  }
 },
 "nbformat": 4,
 "nbformat_minor": 5
}
